Workbook

Sheet P WeeklyS
A1: Date | B1: CAT | C1: SIE | D1: GE | E1: PEP | F1: PG | G1: MMM
A2: 43829 | B2: 148.44 | C2: 104.8939 | D2: 59.5957 | E2: 135.63 | F2: 122.58 | G2: 149.1985
A3: 43836 | B3: 146.13 | C3: 104.5694 | D3: 58.1021 | E3: 134.53 | F3: 123.97 | G3: 150.8874
A4: 43843 | B4: 147.78 | C4: 105.561 | D4: 58.7991 | E4: 141.26 | F4: 126.41 | G4: 151.6231
A5: 43851 | B5: 140.38 | C5: 106.3002 | D5: 58.3012 | E5: 142.915 | F5: 125.14 | G5: 148.9477
A6: 43857 | B6: 131.35 | C6: 100.639 | D6: 61.9855 | E6: 142.02 | F6: 124.62 | G6: 132.6525
A7: 43864 | B7: 133.37 | C7: 97.6281 | D7: 63.8774 | E7: 145.37 | F7: 126.08 | G7: 133.8397
A8: 43871 | B8: 137.99 | C8: 96.1497 | D8: 63.8774 | E8: 146.99 | F8: 126.14 | G8: 134.6172
A9: 43879 | B9: 137.21 | C9: 94.9598 | D9: 60.9898 | E9: 145.85 | F9: 126.7 | G9: 131.206
A10: 43885 | B10: 124.24 | C10: 84.0161 | D10: 54.1689 | E10: 132.03 | F10: 113.23 | G10: 124.7766
A11: 43892 | B11: 121.41 | C11: 78.5713 | D11: 46.8003 | E11: 137.26 | F11: 121.66 | G11: 128.4637
A12: 43899 | B12: 99.64 | C12: 62.7326 | D12: 39.0832 | E12: 127.45 | F12: 114.07 | G12: 118.4558
A13: 43906 | B13: 95.5 | C13: 60.3888 | D13: 32.4615 | E13: 103.93 | F13: 102.43 | G13: 104.418
... A307: 45964 | B307: 563.1 | C307: 237.3 | D307: 307.27 | E307: 142.95 | F307: 146.98 | G307: 164.84
B308: 573.02 | C308: 250.4 | D308: 309.02 | E308: 144.39 | F308: 148.01 | G308: 171.08

Sheet R WeeklyS
A1: Date | B1: CAT | C1: SIE | D1: GE | E1: PEP | F1: PG | G1: MMM
A2: 43829
A3: 43836 | B3: =LN('P WeeklyS'!B3/'P WeeklyS'!B2) -> -0.0156842 | C3: =LN('P WeeklyS'!C3/'P WeeklyS'!C2) -> -0.0030983973 | D3: =LN('P WeeklyS'!D3/'P WeeklyS'!D2) -> -0.025381616 | E3: =LN('P WeeklyS'!E3/'P WeeklyS'!E2) -> -0.0081433675 | F3: =LN('P WeeklyS'!F3/'P WeeklyS'!F2) -> 0.011275723 | G3: =LN('P WeeklyS'!G3/'P WeeklyS'!G2) -> 0.011256229
A4: 43843 | B4: =LN('P WeeklyS'!B4/'P WeeklyS'!B3) -> 0.011228045 | C4: =LN('P WeeklyS'!C4/'P WeeklyS'!C3) -> 0.0094380191 | D4: =LN('P WeeklyS'!D4/'P WeeklyS'!D3) -> 0.011924741 | E4: =LN('P WeeklyS'!E4/'P WeeklyS'!E3) -> 0.048814941 | F4: =LN('P WeeklyS'!F4/'P WeeklyS'!F3) -> 0.019490992 | G4: =LN('P WeeklyS'!G4/'P WeeklyS'!G3) -> 0.004863973
A5: 43851 | B5: =LN('P WeeklyS'!B5/'P WeeklyS'!B4) -> -0.05137165 | C5: =LN('P WeeklyS'!C5/'P WeeklyS'!C4) -> 0.0069781819 | D5: =LN('P WeeklyS'!D5/'P WeeklyS'!D4) -> -0.0085038723 | E5: =LN('P WeeklyS'!E5/'P WeeklyS'!E4) -> 0.011647884 | F5: =LN('P WeeklyS'!F5/'P WeeklyS'!F4) -> -0.010097482 | G5: =LN('P WeeklyS'!G5/'P WeeklyS'!G4) -> -0.017802599
A6: 43857 | B6: =LN('P WeeklyS'!B6/'P WeeklyS'!B5) -> -0.066487515 | C6: =LN('P WeeklyS'!C6/'P WeeklyS'!C5) -> -0.05472731 | D6: =LN('P WeeklyS'!D6/'P WeeklyS'!D5) -> 0.06127781 | E6: =LN('P WeeklyS'!E6/'P WeeklyS'!E5) -> -0.0062821552 | F6: =LN('P WeeklyS'!F6/'P WeeklyS'!F5) -> -0.0041640035 | G6: =LN('P WeeklyS'!G6/'P WeeklyS'!G5) -> -0.11586231
A7: 43864 | B7: =LN('P WeeklyS'!B7/'P WeeklyS'!B6) -> 0.015261705 | C7: =LN('P WeeklyS'!C7/'P WeeklyS'!C6) -> -0.030374495 | D7: =LN('P WeeklyS'!D7/'P WeeklyS'!D6) -> 0.030065134 | E7: =LN('P WeeklyS'!E7/'P WeeklyS'!E6) -> 0.023314324 | F7: =LN('P WeeklyS'!F7/'P WeeklyS'!F6) -> 0.011647519 | G7: =LN('P WeeklyS'!G7/'P WeeklyS'!G6) -> 0.0089098882
A8: 43871 | B8: =LN('P WeeklyS'!B8/'P WeeklyS'!B7) -> 0.034053998 | C8: =LN('P WeeklyS'!C8/'P WeeklyS'!C7) -> -0.01525901 | D8: =LN('P WeeklyS'!D8/'P WeeklyS'!D7) -> 0 | E8: =LN('P WeeklyS'!E8/'P WeeklyS'!E7) -> 0.011082341 | F8: =LN('P WeeklyS'!F8/'P WeeklyS'!F7) -> 0.00047577513 | G8: =LN('P WeeklyS'!G8/'P WeeklyS'!G7) -> 0.0057923799
A9: 43879 | B9: =LN('P WeeklyS'!B9/'P WeeklyS'!B8) -> -0.0056686198 | C9: =LN('P WeeklyS'!C9/'P WeeklyS'!C8) -> -0.012452708 | D9: =LN('P WeeklyS'!D9/'P WeeklyS'!D8) -> -0.046258984 | E9: =LN('P WeeklyS'!E9/'P WeeklyS'!E8) -> -0.0077858609 | F9: =LN('P WeeklyS'!F9/'P WeeklyS'!F8) -> 0.0044296861 | G9: =LN('P WeeklyS'!G9/'P WeeklyS'!G8) -> -0.025666588
A10: 43885 | B10: =LN('P WeeklyS'!B10/'P WeeklyS'!B9) -> -0.09929742 | C10: =LN('P WeeklyS'!C10/'P WeeklyS'!C9) -> -0.1224452 | D10: =LN('P WeeklyS'!D10/'P WeeklyS'!D9) -> -0.11859969 | E10: =LN('P WeeklyS'!E10/'P WeeklyS'!E9) -> -0.099549527 | F10: =LN('P WeeklyS'!F10/'P WeeklyS'!F9) -> -0.11240094 | G10: =LN('P WeeklyS'!G10/'P WeeklyS'!G9) -> -0.050243669
A11: 43892 | B11: =LN('P WeeklyS'!B11/'P WeeklyS'!B10) -> -0.023041931 | C11: =LN('P WeeklyS'!C11/'P WeeklyS'!C10) -> -0.067001954 | D11: =LN('P WeeklyS'!D11/'P WeeklyS'!D10) -> -0.14621733 | E11: =LN('P WeeklyS'!E11/'P WeeklyS'!E10) -> 0.038847768 | F11: =LN('P WeeklyS'!F11/'P WeeklyS'!F10) -> 0.071809121 | G11: =LN('P WeeklyS'!G11/'P WeeklyS'!G10) -> 0.029121436
A12: 43899 | B12: =LN('P WeeklyS'!B12/'P WeeklyS'!B11) -> -0.19760956 | C12: =LN('P WeeklyS'!C12/'P WeeklyS'!C11) -> -0.22512524 | D12: =LN('P WeeklyS'!D12/'P WeeklyS'!D11) -> -0.18019691 | E12: =LN('P WeeklyS'!E12/'P WeeklyS'!E11) -> -0.074152807 | F12: =LN('P WeeklyS'!F12/'P WeeklyS'!F11) -> -0.064417974 | G12: =LN('P WeeklyS'!G12/'P WeeklyS'!G11) -> -0.081106479
A13: 43906 | B13: =LN('P WeeklyS'!B13/'P WeeklyS'!B12) -> -0.042437443 | C13: =LN('P WeeklyS'!C13/'P WeeklyS'!C12) -> -0.038077591 | D13: =LN('P WeeklyS'!D13/'P WeeklyS'!D12) -> -0.18563794 | E13: =LN('P WeeklyS'!E13/'P WeeklyS'!E12) -> -0.20400654 | F13: =LN('P WeeklyS'!F13/'P WeeklyS'!F12) -> -0.10763266 | G13: =LN('P WeeklyS'!G13/'P WeeklyS'!G12) -> -0.12613782
A14: 43913 | B14: =LN('P WeeklyS'!B14/'P WeeklyS'!B13) -> 0.099015823 | C14: =LN('P WeeklyS'!C14/'P WeeklyS'!C13) -> 0.085230903 | D14: =LN('P WeeklyS'!D14/'P WeeklyS'!D13) -> 0.15590111 | E14: =LN('P WeeklyS'!E14/'P WeeklyS'!E13) -> 0.14760015 | F14: =LN('P WeeklyS'!F14/'P WeeklyS'!F13) -> 0.072844989 | G14: =LN('P WeeklyS'!G14/'P WeeklyS'!G13) -> 0.064718969
... A307: 45964 | B307: =LN('P WeeklyS'!B307/'P WeeklyS'!B306) -> -0.024835539 | C307: =LN('P WeeklyS'!C307/'P WeeklyS'!C306) -> -0.034175429 | D307: =LN('P WeeklyS'!D307/'P WeeklyS'!D306) -> -0.0054526116 | E307: =LN('P WeeklyS'!E307/'P WeeklyS'!E306) -> -0.021727951 | F307: =LN('P WeeklyS'!F307/'P WeeklyS'!F306) -> -0.0228024 | G307: =LN('P WeeklyS'!G307/'P WeeklyS'!G306) -> -0.010020003

Sheet P WeeklyC
A1: Date | B1: BTC-USD | C1: ETHUSD | D1: XRP | E1: SOL | F1: TRX
A2: 43828 | B2: 7270.25 | C2: 132.18 | D2: 0.1923 | E2: 1.39 | F2: 0.6429
A3: 43835 | B3: 8037.58 | C3: 142.77 | D3: 0.213 | E3: 1.36 | F3: 0.6049
A4: 43842 | B4: 8904.95 | C4: 170.78 | D4: 0.2453 | E4: 1.4 | F4: 0.5431
A5: 43849 | B5: 8513 | C5: 163.25 | D5: 0.223 | E5: 1.34 | F5: 0.56
A6: 43856 | B6: 9383.8 | C6: 180.37 | D6: 0.2385 | E6: 1.3095 | F6: 0.5558
A7: 43863 | B7: 9748 | C7: 219.22 | D7: 0.2774 | E7: 1.32 | F7: 0.5409
A8: 43870 | B8: 10316 | C8: 282.61 | D8: 0.3352 | E8: 1.5 | F8: 0.5051
A9: 43877 | B9: 9663.1 | C9: 262.81 | D9: 0.2726 | E9: 1.7055 | F9: 0.63
A10: 43884 | B10: 8668.22 | C10: 226 | D10: 0.236 | E10: 1.31 | F10: 0.5
A11: 43891 | B11: 9130.5 | C11: 240.85 | D11: 0.2432 | E11: 1.27 | F11: 0.52
A12: 43898 | B12: 5431.41 | C12: 128.86 | D12: 0.1536 | E12: 0.9273 | F12: 0.41
A13: 43905 | B13: 5991.49 | C13: 125.24 | D13: 0.1519 | E13: 1.03 | F13: 0.555
... A304: 45950 | B304: 111451.59 | C304: 3947.53 | D304: 2.3375 | E304: 1.82 | F304: 0.7238
A305: 45956 | B305: 109445.66 | C305: 3860.43 | E305: 1.86 | F305: 0.694
A306: 45963 | B306: 102310.84 | C306: 3407.84 | E306: 1.86 | F306: 0.6252
A307: 45970 | B307: 104507.69 | C307: 3578.81 | E307: 1.89 | F307: 0.5959

Sheet R WeeklyC 
A1: Date | B1: BTC-USD | C1: ETHUSD | D1: XRP | E1: SOL | F1: TRX
A2: 43828
A3: 43835 | B3: =LN('P WeeklyC'!B3/'P WeeklyC'!B2) -> 0.10033736 | C3: =LN('P WeeklyC'!C3/'P WeeklyC'!C2) -> 0.077070314 | D3: =LN('P WeeklyC'!D3/'P WeeklyC'!D2) -> 0.10223551 | E3: =LN('P WeeklyC'!E3/'P WeeklyC'!E2) -> -0.021819047 | F3: =LN('P WeeklyC'!F3/'P WeeklyC'!F2) -> -0.060926036
A4: 43842 | B4: =LN('P WeeklyC'!B4/'P WeeklyC'!B3) -> 0.10247926 | C4: =LN('P WeeklyC'!C4/'P WeeklyC'!C3) -> 0.17914123 | D4: =LN('P WeeklyC'!D4/'P WeeklyC'!D3) -> 0.14118979 | E4: =LN('P WeeklyC'!E4/'P WeeklyC'!E3) -> 0.028987537 | F4: =LN('P WeeklyC'!F4/'P WeeklyC'!F3) -> -0.10776969
A5: 43849 | B5: =LN('P WeeklyC'!B5/'P WeeklyC'!B4) -> -0.045012895 | C5: =LN('P WeeklyC'!C5/'P WeeklyC'!C4) -> -0.04509341 | D5: =LN('P WeeklyC'!D5/'P WeeklyC'!D4) -> -0.09531018 | E5: =LN('P WeeklyC'!E5/'P WeeklyC'!E4) -> -0.043802623 | F5: =LN('P WeeklyC'!F5/'P WeeklyC'!F4) -> 0.030643319
A6: 43856 | B6: =LN('P WeeklyC'!B6/'P WeeklyC'!B5) -> 0.097390391 | C6: =LN('P WeeklyC'!C6/'P WeeklyC'!C5) -> 0.099727529 | D6: =LN('P WeeklyC'!D6/'P WeeklyC'!D5) -> 0.067197539 | E6: =LN('P WeeklyC'!E6/'P WeeklyC'!E5) -> -0.023024229 | F6: =LN('P WeeklyC'!F6/'P WeeklyC'!F5) -> -0.0075282664
A7: 43863 | B7: =LN('P WeeklyC'!B7/'P WeeklyC'!B6) -> 0.038077338 | C7: =LN('P WeeklyC'!C7/'P WeeklyC'!C6) -> 0.1950655 | D7: =LN('P WeeklyC'!D7/'P WeeklyC'!D6) -> 0.1510912 | E7: =LN('P WeeklyC'!E7/'P WeeklyC'!E6) -> 0.0079863516 | F7: =LN('P WeeklyC'!F7/'P WeeklyC'!F6) -> -0.027174098
A8: 43870 | B8: =LN('P WeeklyC'!B8/'P WeeklyC'!B7) -> 0.056633952 | C8: =LN('P WeeklyC'!C8/'P WeeklyC'!C7) -> 0.25399206 | D8: =LN('P WeeklyC'!D8/'P WeeklyC'!D7) -> 0.18926686 | E8: =LN('P WeeklyC'!E8/'P WeeklyC'!E7) -> 0.12783337 | F8: =LN('P WeeklyC'!F8/'P WeeklyC'!F7) -> -0.068477989
A9: 43877 | B9: =LN('P WeeklyC'!B9/'P WeeklyC'!B8) -> -0.06538158 | C9: =LN('P WeeklyC'!C9/'P WeeklyC'!C8) -> -0.072636518 | D9: =LN('P WeeklyC'!D9/'P WeeklyC'!D8) -> -0.20672185 | E9: =LN('P WeeklyC'!E9/'P WeeklyC'!E8) -> 0.12839321 | F9: =LN('P WeeklyC'!F9/'P WeeklyC'!F8) -> 0.22096339
A10: 43884 | B10: =LN('P WeeklyC'!B10/'P WeeklyC'!B9) -> -0.10865104 | C10: =LN('P WeeklyC'!C10/'P WeeklyC'!C9) -> -0.15089634 | D10: =LN('P WeeklyC'!D10/'P WeeklyC'!D9) -> -0.14417371 | E10: =LN('P WeeklyC'!E10/'P WeeklyC'!E9) -> -0.26383119 | F10: =LN('P WeeklyC'!F10/'P WeeklyC'!F9) -> -0.23111172
A11: 43891 | B11: =LN('P WeeklyC'!B11/'P WeeklyC'!B10) -> 0.051956994 | C11: =LN('P WeeklyC'!C11/'P WeeklyC'!C10) -> 0.063639334 | D11: =LN('P WeeklyC'!D11/'P WeeklyC'!D10) -> 0.030052345 | E11: =LN('P WeeklyC'!E11/'P WeeklyC'!E10) -> -0.031010237 | F11: =LN('P WeeklyC'!F11/'P WeeklyC'!F10) -> 0.039220713
A12: 43898 | B12: =LN('P WeeklyC'!B12/'P WeeklyC'!B11) -> -0.51942169 | C12: =LN('P WeeklyC'!C12/'P WeeklyC'!C11) -> -0.62544779 | D12: =LN('P WeeklyC'!D12/'P WeeklyC'!D11) -> -0.45953233 | E12: =LN('P WeeklyC'!E12/'P WeeklyC'!E11) -> -0.31449504 | F12: =LN('P WeeklyC'!F12/'P WeeklyC'!F11) -> -0.23767165
A13: 43905 | B13: =LN('P WeeklyC'!B13/'P WeeklyC'!B12) -> 0.09814136 | C13: =LN('P WeeklyC'!C13/'P WeeklyC'!C12) -> -0.028494647 | D13: =LN('P WeeklyC'!D13/'P WeeklyC'!D12) -> -0.011129411 | E13: =LN('P WeeklyC'!E13/'P WeeklyC'!E12) -> 0.10503694 | F13: =LN('P WeeklyC'!F13/'P WeeklyC'!F12) -> 0.30281095
A14: 43912 | B14: =LN('P WeeklyC'!B14/'P WeeklyC'!B13) -> 0.10907721 | C14: =LN('P WeeklyC'!C14/'P WeeklyC'!C13) -> 0.093682887 | D14: =LN('P WeeklyC'!D14/'P WeeklyC'!D13) -> 0.18681004 | E14: =LN('P WeeklyC'!E14/'P WeeklyC'!E13) -> 0.12744495 | F14: =LN('P WeeklyC'!F14/'P WeeklyC'!F13) -> -0.08025294
... A307: 45970 | B307: =LN('P WeeklyC'!B307/'P WeeklyC'!B306) -> 0.021245027 | C307: =LN('P WeeklyC'!C307/'P WeeklyC'!C306) -> 0.048951683 | D307: =LN('P WeeklyC'!D307/'P WeeklyC'!D306) -> #DIV/0! | E307: =LN('P WeeklyC'!E307/'P WeeklyC'!E306) -> 0.016000341 | F307: =LN('P WeeklyC'!F307/'P WeeklyC'!F306) -> -0.047998731

Sheet Stocks
B1: Start | C1: 43831
B2: End | C2: =TODAY() -> 45974
C4: Diarios | K4: Semanales | S4: Mensual
C5: AMZN | D5: MSFT | E5: AAPL | F5: GOOGL | G5: META | H5: NVDA | K5: CAT | L5: SIE | M5: GE | N5: PEP | O5: PG | P5: MMM | S5: AMZN | T5: MSFT | U5: AAPL | V5: GOOGL | W5: META | X5: NVDA
B6: 43832 | C6: 94.9005 | D6: 160.62 | E6: 75.0875 | F6: 68.434 | G6: 209.78 | H6: 5.9978 | J6: 43828 | K6: {=_xlfn.STOCKHISTORY(K5,$C$1,$C$2,1,0,1)} -> 148.44 | L6: {=_xlfn.STOCKHISTORY(L5,$C$1,$C$2,1,0,1)} -> 104.8939 | M6: {=_xlfn.STOCKHISTORY(M5,$C$1,$C$2,1,0,1)} -> 59.5957 | N6: {=_xlfn.STOCKHISTORY(N5,$C$1,$C$2,1,0,1)} -> 135.63 | O6: {=_xlfn.STOCKHISTORY(O5,$C$1,$C$2,1,0,1)} -> 122.58 | P6: {=_xlfn.STOCKHISTORY(P5,$C$1,$C$2,1,0,1)} -> 149.1985 | R6: 43831 | S6: 100.436 | T6: 170.23 | U6: 77.3775 | V6: 71.639 | W6: 201.91 | X6: 5.9108
B7: 43833 | C7: 93.7485 | D7: 158.62 | E7: 74.3575 | F7: 68.076 | G7: 208.67 | H7: 5.9018 | J7: 43835 | K7: 146.13 | L7: 104.5694 | M7: 58.1021 | N7: 134.53 | O7: 123.97 | P7: 150.8874 | R7: 43862 | S7: 94.1875 | T7: 162.01 | U7: 68.34 | V7: 66.9625 | W7: 192.47 | X7: 6.7518
B8: 43836 | C8: 95.144 | D8: 159.03 | E8: 74.95 | F8: 69.8905 | G8: 212.6 | H8: 5.9265 | J8: 43842 | K8: 147.78 | L8: 105.561 | M8: 58.7991 | N8: 141.26 | O8: 126.41 | P8: 151.6231 | R8: 43891 | S8: 97.486 | T8: 157.71 | U8: 63.5725 | V8: 58.0975 | W8: 166.8 | X8: 6.59
B9: 43837 | C9: 95.343 | D9: 157.58 | E9: 74.5975 | F9: 69.7555 | G9: 213.06 | H9: 5.9983 | J9: 43849 | K9: 140.38 | L9: 106.3002 | M9: 58.3012 | N9: 142.915 | O9: 125.14 | P9: 148.9477 | R9: 43922 | S9: 123.7 | T9: 179.21 | U9: 73.45 | V9: 67.335 | W9: 204.71 | X9: 7.307
B10: 43838 | C10: 94.5985 | D10: 160.09 | E10: 75.7975 | F10: 70.252 | G10: 215.22 | H10: 6.0095 | J10: 43856 | K10: 131.35 | L10: 100.639 | M10: 61.9855 | N10: 142.02 | O10: 124.62 | P10: 132.6525 | R10: 43952 | S10: 122.1185 | T10: 183.25 | U10: 79.485 | V10: 71.676 | W10: 225.09 | X10: 8.8755
B11: 43839 | C11: 95.0525 | D11: 162.09 | E11: 77.4075 | F11: 70.9895 | G11: 218.3 | H11: 6.0755 | J11: 43863 | K11: 133.37 | L11: 97.6281 | M11: 63.8774 | N11: 145.37 | O11: 126.08 | P11: 133.8397 | R11: 43983 | S11: 137.941 | T11: 203.51 | U11: 91.2 | V11: 70.9025 | W11: 227.07 | X11: 9.4978
B12: 43840 | C12: 94.158 | D12: 161.34 | E12: 77.5825 | F12: 71.448 | G12: 218.06 | H12: 6.108 | J12: 43870 | K12: 137.99 | L12: 96.1497 | M12: 63.8774 | N12: 146.99 | O12: 126.14 | P12: 134.6172 | R12: 44013 | S12: 158.234 | T12: 205.01 | U12: 106.26 | V12: 74.3975 | W12: 253.67 | X12: 10.6148
B13: 43843 | C13: 94.565 | D13: 163.28 | E13: 79.24 | F13: 72.0015 | G13: 221.91 | H13: 6.2995 | J13: 43877 | K13: 137.21 | L13: 94.9598 | M13: 60.9898 | N13: 145.85 | O13: 126.7 | P13: 131.206 | R13: 44044 | S13: 172.548 | T13: 225.53 | U13: 129.04 | V13: 81.4765 | W13: 293.2 | X13: 13.3745
B14: 43844 | C14: 93.472 | D14: 162.13 | E14: 78.17 | F14: 71.5295 | G14: 219.06 | H14: 6.182 | J14: 43884 | K14: 124.24 | L14: 84.0161 | M14: 54.1689 | N14: 132.03 | O14: 113.23 | P14: 124.7766 | R14: 44075 | S14: 157.4365 | T14: 210.33 | U14: 115.81 | V14: 73.28 | W14: 261.9 | X14: 13.5305
B15: 43845 | C15: 93.101 | D15: 163.18 | E15: 77.835 | F15: 71.96 | G15: 221.15 | H15: 6.1393 | J15: 43891 | K15: 121.41 | L15: 78.5713 | M15: 46.8003 | N15: 137.26 | O15: 121.66 | P15: 128.4637 | R15: 44105 | S15: 151.8075 | T15: 202.47 | U15: 108.86 | V15: 80.8055 | W15: 263.11 | X15: 12.534
B16: 43846 | C16: 93.897 | D16: 166.17 | E16: 78.81 | F16: 72.508 | G16: 221.77 | H16: 6.2233 | J16: 43898 | K16: 99.64 | L16: 62.7326 | M16: 39.0832 | N16: 127.45 | O16: 114.07 | P16: 118.4558 | R16: 44136 | S16: 158.402 | T16: 214.07 | U16: 119.05 | V16: 87.72 | W16: 276.97 | X16: 13.4015
B17: 43847 | C17: 93.236 | D17: 167.1 | E17: 79.6825 | F17: 73.976 | G17: 222.14 | H17: 6.232 | J17: 43905 | K17: 95.5 | L17: 60.3888 | M17: 32.4615 | N17: 103.93 | O17: 102.43 | P17: 104.418 | R17: 44166 | S17: 162.8465 | T17: 222.42 | U17: 132.69 | V17: 87.632 | W17: 273.16 | X17: 13.055
B18: 43851 | C18: 94.6 | D18: 166.5 | E18: 79.1425 | F18: 74.1125 | G18: 221.44 | H18: 6.1985 | J18: 43912 | K18: 105.44 | L18: 65.7615 | M18: 37.9381 | N18: 120.46 | O18: 110.17 | P18: 111.3993 | R18: 44197 | S18: 160.31 | T18: 231.96 | U18: 131.96 | V18: 91.368 | W18: 258.33 | X18: 12.9898
... B76: 43935 | C76: 114.166 | D76: 173.7 | E76: 71.7625 | F76: 63.2615 | G76: 178.17 | H76: 7.0988 | J76: 44318 | K76: 240.99 | L76: 144.28 | M76: 66.2175 | N76: 145.56 | O76: 135.15 | P76: 169.7828 | R76: 45962 | S76: 244.41 | T76: 496.82 | U76: 268.47 | V76: 278.83 | W76: 621.71 | X76: 188.15
B77: 43936 | C77: 115.384 | D77: 171.88 | E77: 71.1075 | F77: 62.865 | G77: 176.97 | H77: 7.021 | J77: 44325 | K77: 242.23 | L77: 144.48 | M77: 66.0183 | N77: 146.59 | O77: 138.01 | P77: 170.878
B78: 43937 | C78: 120.4095 | D78: 177.04 | E78: 71.6725 | F78: 62.8715 | G78: 176.25 | H78: 7.3675 | J78: 44332 | K78: 237.24 | L78: 135.86 | M78: 65.8689 | N78: 147.1 | O78: 138 | P78: 168.7711
B79: 43938 | C79: 118.75 | D79: 178.6 | E79: 70.7 | F79: 63.95 | G79: 179.24 | H79: 7.308 | J79: 44339 | K79: 241.08 | L79: 134.9 | M79: 70.0013 | N79: 147.94 | O79: 134.85 | P79: 169.7577
B80: 43941 | C80: 119.6805 | D80: 175.06 | E80: 69.2325 | F80: 63.0575 | G80: 178.24 | H80: 7.1763 | J80: 44346 | K80: 244.02 | L80: 136 | M80: 69.5034 | N80: 147.84 | O80: 135.95 | P80: 172.2743
B81: 43942 | C81: 116.406 | D81: 167.82 | E81: 67.0925 | F81: 60.608 | G81: 170.8 | H81: 6.7378 | J81: 44353 | K81: 220.7 | L81: 136.72 | M81: 68.1592 | N81: 147.69 | O81: 134.86 | P81: 169.5654
B82: 43943 | C82: 118.1745 | D82: 173.52 | E82: 69.025 | F82: 62.9205 | G82: 182.28 | H82: 7.1538 | J82: 44360 | K82: 208.86 | L82: 133.7 | M82: 63.6285 | N82: 145.42 | O82: 132.03 | P82: 160.1929
B83: 43944 | C83: 119.9725 | D83: 171.42 | E83: 68.7575 | F83: 63.5585 | G83: 185.13 | H83: 7.1003 | J83: 44367 | K83: 216.31 | L83: 136.92 | M83: 65.5204 | N83: 146.41 | O83: 134.92 | P83: 162.8266
B84: 43945 | C84: 120.511 | D84: 174.55 | E84: 70.7425 | F84: 63.83 | G84: 190.07 | H84: 7.2398 | J84: 44374 | K84: 217.76 | L84: 133.86 | M84: 66.5162 | N84: 148.91 | O84: 135.9 | P84: 167.124
B85: 43948 | C85: 118.8 | D85: 174.05 | E85: 70.7925 | F85: 63.543 | G85: 187.5 | H85: 7.427 | J85: 44381 | K85: 217.42 | L85: 132.84 | M85: 65.5204 | N85: 149.48 | O85: 137.03 | P85: 168.0521
B86: 43949 | C86: 115.704 | D86: 169.81 | E86: 69.645 | F86: 61.6295 | G86: 182.91 | H86: 7.284 | J86: 44388 | K86: 207.95 | L86: 129.4 | M86: 62.4834 | N86: 155.82 | O86: 140.51 | P86: 166.6893
B87: 43950 | C87: 118.6355 | D87: 177.43 | E87: 71.9325 | F87: 67.109 | G87: 194.19 | H87: 7.4615 | J87: 44395 | K87: 209.53 | L87: 134.56 | M87: 63.28 | N87: 157.18 | O87: 139.79 | P87: 167.6257
B88: 43951 | C88: 123.7 | D88: 179.21 | E88: 73.45 | F88: 67.335 | G88: 204.71 | H88: 7.307 | J88: 44402 | K88: 206.75 | L88: 131.58 | M88: 64.4749 | N88: 156.95 | O88: 142.23 | P88: 165.4937
... B311: 44274 | C311: 153.748 | D311: 230.35 | E311: 119.99 | F311: 101.348 | G311: 290.11 | H311: 12.8458 | J311: 45970 | K311: 563.1 | L311: 237.3 | M311: 307.27 | N311: 142.95 | O311: 146.98 | P311: 164.84
B312: 44277 | C312: 155.5435 | D312: 235.99 | E312: 123.39 | F312: 101.5345 | G312: 293.54 | H312: 13.1863 | K312: 573.02 | L312: 250.4 | M312: 309.02 | N312: 144.39 | O312: 148.01 | P312: 171.08
B313: 44278 | C313: 156.875 | D313: 237.58 | E313: 122.54 | F313: 102.0665 | G313: 290.63 | H313: 13.0708
B314: 44279 | C314: 154.3535 | D314: 235.46 | E314: 120.09 | F314: 101.6265 | G314: 282.14 | H314: 12.643
B315: 44280 | C315: 152.313 | D315: 232.34 | E315: 120.59 | F315: 101.623 | G315: 278.74 | H315: 12.5353
B316: 44281 | C316: 152.6015 | D316: 236.48 | E316: 121.21 | F316: 101.2365 | G316: 283.02 | H316: 12.8393
B317: 44284 | C317: 153.7865 | D317: 235.24 | E317: 121.39 | F317: 102.2895 | G317: 290.82 | H317: 12.9483
B318: 44285 | C318: 152.7645 | D318: 231.85 | E318: 119.9 | F318: 102.3235 | G318: 288 | H318: 12.8718
B319: 44286 | C319: 154.704 | D319: 235.77 | E319: 122.15 | F319: 103.126 | G319: 294.53 | H319: 13.3483
B320: 44287 | C320: 158.05 | D320: 242.35 | E320: 123 | F320: 106.489 | G320: 298.66 | H320: 13.8118
...

Sheet Stock
B1: Start | C1: 43831
B2: End | C2: =TODAY() -> 45974
C4: Diarios | K4: Semanales | S4: Mensual
C5: AMZN | D5: MSFT | E5: AAPL | F5: GOOGL | G5: META | H5: NVDA | K5: AMZN | L5: MSFT | M5: AAPL | N5: GOOGL | O5: META | P5: NVDA | S5: AMZN | T5: MSFT | U5: AAPL | V5: GOOGL | W5: META | X5: NVDA
B6: 43832 | C6: 94.9005 | D6: 160.62 | E6: 75.0875 | F6: 68.434 | G6: 209.78 | H6: 5.9978 | J6: 43829 | K6: 93.7485 | L6: 158.62 | M6: 74.3575 | N6: 68.076 | O6: 208.67 | P6: 5.9018 | R6: 43831 | S6: 100.436 | T6: 170.23 | U6: 77.3775 | V6: 71.639 | W6: 201.91 | X6: 5.9108
B7: 43833 | C7: 93.7485 | D7: 158.62 | E7: 74.3575 | F7: 68.076 | G7: 208.67 | H7: 5.9018 | J7: 43836 | K7: 94.158 | L7: 161.34 | M7: 77.5825 | N7: 71.448 | O7: 218.06 | P7: 6.108 | R7: 43862 | S7: 94.1875 | T7: 162.01 | U7: 68.34 | V7: 66.9625 | W7: 192.47 | X7: 6.7518
B8: 43836 | C8: 95.144 | D8: 159.03 | E8: 74.95 | F8: 69.8905 | G8: 212.6 | H8: 5.9265 | J8: 43843 | K8: 93.236 | L8: 167.1 | M8: 79.6825 | N8: 73.976 | O8: 222.14 | P8: 6.232 | R8: 43891 | S8: 97.486 | T8: 157.71 | U8: 63.5725 | V8: 58.0975 | W8: 166.8 | X8: 6.59
B9: 43837 | C9: 95.343 | D9: 157.58 | E9: 74.5975 | F9: 69.7555 | G9: 213.06 | H9: 5.9983 | J9: 43851 | K9: 93.082 | L9: 165.04 | M9: 79.5775 | N9: 73.3085 | O9: 217.94 | P9: 6.262 | R9: 43922 | S9: 123.7 | T9: 179.21 | U9: 73.45 | V9: 67.335 | W9: 204.71 | X9: 7.307
B10: 43838 | C10: 94.5985 | D10: 160.09 | E10: 75.7975 | F10: 70.252 | G10: 215.22 | H10: 6.0095 | J10: 43857 | K10: 100.436 | L10: 170.23 | M10: 77.3775 | N10: 71.639 | O10: 201.91 | P10: 5.9108 | R10: 43952 | S10: 122.1185 | T10: 183.25 | U10: 79.485 | V10: 71.676 | W10: 225.09 | X10: 8.8755
B11: 43839 | C11: 95.0525 | D11: 162.09 | E11: 77.4075 | F11: 70.9895 | G11: 218.3 | H11: 6.0755 | J11: 43864 | K11: 103.964 | L11: 183.89 | M11: 80.0075 | N11: 73.9555 | O11: 212.33 | P11: 6.2898 | R11: 43983 | S11: 137.941 | T11: 203.51 | U11: 91.2 | V11: 70.9025 | W11: 227.07 | X11: 9.4978
B12: 43840 | C12: 94.158 | D12: 161.34 | E12: 77.5825 | F12: 71.448 | G12: 218.06 | H12: 6.108 | J12: 43871 | K12: 106.7435 | L12: 185.35 | M12: 81.2375 | N12: 75.9365 | O12: 214.18 | P12: 7.2448 | R12: 44013 | S12: 158.234 | T12: 205.01 | U12: 106.26 | V12: 74.3975 | W12: 253.67 | X12: 10.6148
B13: 43843 | C13: 94.565 | D13: 163.28 | E13: 79.24 | F13: 72.0015 | G13: 221.91 | H13: 6.2995 | J13: 43879 | K13: 104.7985 | L13: 178.59 | M13: 78.2625 | N13: 74.173 | O13: 210.18 | P13: 7.3518 | R13: 44044 | S13: 172.548 | T13: 225.53 | U13: 129.04 | V13: 81.4765 | W13: 293.2 | X13: 13.3745
B14: 43844 | C14: 93.472 | D14: 162.13 | E14: 78.17 | F14: 71.5295 | G14: 219.06 | H14: 6.182 | J14: 43885 | K14: 94.1875 | L14: 162.01 | M14: 68.34 | N14: 66.9625 | O14: 192.47 | P14: 6.7518 | R14: 44075 | S14: 157.4365 | T14: 210.33 | U14: 115.81 | V14: 73.28 | W14: 261.9 | X14: 13.5305
B15: 43845 | C15: 93.101 | D15: 163.18 | E15: 77.835 | F15: 71.96 | G15: 221.15 | H15: 6.1393 | J15: 43892 | K15: 95.0545 | L15: 161.57 | M15: 72.2575 | N15: 64.787 | O15: 181.09 | P15: 6.651 | R15: 44105 | S15: 151.8075 | T15: 202.47 | U15: 108.86 | V15: 80.8055 | W15: 263.11 | X15: 12.534
B16: 43846 | C16: 93.897 | D16: 166.17 | E16: 78.81 | F16: 72.508 | G16: 221.77 | H16: 6.2233 | J16: 43899 | K16: 89.25 | L16: 158.83 | M16: 69.4925 | N16: 60.7135 | O16: 170.28 | P16: 6.021 | R16: 44136 | S16: 158.402 | T16: 214.07 | U16: 119.05 | V16: 87.72 | W16: 276.97 | X16: 13.4015
B17: 43847 | C17: 93.236 | D17: 167.1 | E17: 79.6825 | F17: 73.976 | G17: 222.14 | H17: 6.232 | J17: 43906 | K17: 92.3045 | L17: 137.35 | M17: 57.31 | N17: 53.4105 | O17: 149.73 | P17: 5.1438 | R17: 44166 | S17: 162.8465 | T17: 222.42 | U17: 132.69 | V17: 87.632 | W17: 273.16 | X17: 13.055
... B76: 43935 | C76: 114.166 | D76: 173.7 | E76: 71.7625 | F76: 63.2615 | G76: 178.17 | H76: 7.0988 | J76: 44319 | K76: 164.5805 | L76: 252.46 | M76: 130.21 | N76: 117.5965 | O76: 319.08 | P76: 14.8123 | R76: 45962 | S76: 244.41 | T76: 496.82 | U76: 268.47 | V76: 278.83 | W76: 621.71 | X76: 188.15
B77: 43936 | C77: 115.384 | D77: 171.88 | E77: 71.1075 | F77: 62.865 | G77: 176.97 | H77: 7.021 | J77: 44326 | K77: 161.145 | L77: 248.15 | M77: 127.45 | N77: 113.919 | O77: 315.94 | P77: 14.243
B78: 43937 | C78: 120.4095 | D78: 177.04 | E78: 71.6725 | F78: 62.8715 | G78: 176.25 | H78: 7.3675 | J78: 44333 | K78: 160.154 | L78: 245.17 | M78: 125.43 | N78: 114.7065 | O78: 316.23 | P78: 14.9918
B79: 43938 | C79: 118.75 | D79: 178.6 | E79: 70.7 | F79: 63.95 | G79: 179.24 | H79: 7.308 | J79: 44340 | K79: 161.1535 | L79: 249.68 | M79: 124.61 | N79: 117.8425 | O79: 328.73 | P79: 16.2445
B80: 43941 | C80: 119.6805 | D80: 175.06 | E80: 69.2325 | F80: 63.0575 | G80: 178.24 | H80: 7.1763 | J80: 44348 | K80: 160.311 | L80: 250.79 | M80: 125.89 | N80: 119.6785 | O80: 330.35 | P80: 17.5783
B81: 43942 | C81: 116.406 | D81: 167.82 | E81: 67.0925 | F81: 60.608 | G81: 170.8 | H81: 6.7378 | J81: 44354 | K81: 167.3415 | L81: 257.89 | M81: 127.35 | N81: 121.51 | O81: 331.26 | P81: 17.8253
B82: 43943 | C82: 118.1745 | D82: 173.52 | E82: 69.025 | F82: 62.9205 | G82: 182.28 | H82: 7.1538 | J82: 44361 | K82: 174.345 | L82: 259.43 | M82: 130.46 | N82: 120.111 | O82: 329.66 | P82: 18.6387
B83: 43944 | C83: 119.9725 | D83: 171.42 | E83: 68.7575 | F83: 63.5585 | G83: 185.13 | H83: 7.1003 | J83: 44368 | K83: 170.073 | L83: 265.02 | M83: 133.11 | N83: 122.5085 | O83: 341.37 | P83: 19.031
B84: 43945 | C84: 120.511 | D84: 174.55 | E84: 70.7425 | F84: 63.83 | G84: 190.07 | H84: 7.2398 | J84: 44375 | K84: 175.549 | L84: 277.65 | M84: 139.96 | N84: 125.2575 | O84: 354.7 | P84: 20.487
B85: 43948 | C85: 118.8 | D85: 174.05 | E85: 70.7925 | F85: 63.543 | G85: 187.5 | H85: 7.427 | J85: 44383 | K85: 185.967 | L85: 277.94 | M85: 145.11 | N85: 125.5185 | O85: 350.42 | P85: 20.0503
B86: 43949 | C86: 115.704 | D86: 169.81 | E86: 69.645 | F86: 61.6295 | G86: 182.91 | H86: 7.284 | J86: 44389 | K86: 178.6815 | L86: 280.75 | M86: 146.39 | N86: 126.97 | O86: 341.16 | P86: 18.161
B87: 43950 | C87: 118.6355 | D87: 177.43 | E87: 71.9325 | F87: 67.109 | G87: 194.19 | H87: 7.4615 | J87: 44396 | K87: 182.832 | L87: 289.67 | M87: 148.56 | N87: 133.015 | O87: 369.79 | P87: 19.558
B88: 43951 | C88: 123.7 | D88: 179.21 | E88: 73.45 | F88: 67.335 | G88: 204.71 | H88: 7.307 | J88: 44403 | K88: 166.3795 | L88: 284.91 | M88: 145.86 | N88: 134.7265 | O88: 356.3 | P88: 19.499
... B311: 44274 | C311: 153.748 | D311: 230.35 | E311: 119.99 | F311: 101.348 | G311: 290.11 | H311: 12.8458 | J311: 45964 | K311: 244.41 | L311: 496.82 | M311: 268.47 | N311: 278.83 | O311: 621.71 | P311: 188.15
B312: 44277 | C312: 155.5435 | D312: 235.99 | E312: 123.39 | F312: 101.5345 | G312: 293.54 | H312: 13.1863
B313: 44278 | C313: 156.875 | D313: 237.58 | E313: 122.54 | F313: 102.0665 | G313: 290.63 | H313: 13.0708
B314: 44279 | C314: 154.3535 | D314: 235.46 | E314: 120.09 | F314: 101.6265 | G314: 282.14 | H314: 12.643
B315: 44280 | C315: 152.313 | D315: 232.34 | E315: 120.59 | F315: 101.623 | G315: 278.74 | H315: 12.5353
B316: 44281 | C316: 152.6015 | D316: 236.48 | E316: 121.21 | F316: 101.2365 | G316: 283.02 | H316: 12.8393
B317: 44284 | C317: 153.7865 | D317: 235.24 | E317: 121.39 | F317: 102.2895 | G317: 290.82 | H317: 12.9483
B318: 44285 | C318: 152.7645 | D318: 231.85 | E318: 119.9 | F318: 102.3235 | G318: 288 | H318: 12.8718
B319: 44286 | C319: 154.704 | D319: 235.77 | E319: 122.15 | F319: 103.126 | G319: 294.53 | H319: 13.3483
B320: 44287 | C320: 158.05 | D320: 242.35 | E320: 123 | F320: 106.489 | G320: 298.66 | H320: 13.8118
B321: 44291 | C321: 161.3365 | D321: 249.07 | E321: 125.9 | F321: 110.948 | G321: 308.91 | H321: 13.9875
...
